<?xml version="1.0" encoding="UTF-8"?>
<!-- Generated by org.testng.reporters.JUnitReportReporter -->
<testsuite skipped="0" hostname="EPRURYAW0060" name="com.epam.test.calculator.suites.test.negative.TrigonometricOperators" tests="2" failures="0" timestamp="19 Mar 2018 12:48:15 GMT" time="0.013" errors="2">
  <testcase name="testCtg" time="0.005" classname="com.epam.test.calculator.suites.test.negative.TrigonometricOperators">
    <error type="org.testng.TestException" message="
Method TrigonometricOperators.testCtg()[pri:0, instance:com.epam.test.calculator.suites.test.negative.TrigonometricOperators@323b36e0] should have thrown an exception of type class java.lang.Exception">
      <![CDATA[org.testng.TestException: 
Method TrigonometricOperators.testCtg()[pri:0, instance:com.epam.test.calculator.suites.test.negative.TrigonometricOperators@323b36e0] should have thrown an exception of type class java.lang.Exception
at org.testng.internal.ExpectedExceptionsHolder.noException(ExpectedExceptionsHolder.java:80)
at org.testng.internal.Invoker.considerExceptions(Invoker.java:1139)
at org.testng.internal.Invoker.invokeMethod(Invoker.java:612)
at org.testng.internal.Invoker.invokeTestMethod(Invoker.java:716)
at org.testng.internal.Invoker.invokeTestMethods(Invoker.java:988)
at org.testng.internal.TestMethodWorker.invokeTestMethods(TestMethodWorker.java:125)
at org.testng.internal.TestMethodWorker.run(TestMethodWorker.java:109)
at java.util.concurrent.ThreadPoolExecutor.runWorker(ThreadPoolExecutor.java:1149)
at java.util.concurrent.ThreadPoolExecutor$Worker.run(ThreadPoolExecutor.java:624)
at java.lang.Thread.run(Thread.java:748)
]]>
    </error>
  </testcase> <!-- testCtg -->
  <testcase name="testTg" time="0.008" classname="com.epam.test.calculator.suites.test.negative.TrigonometricOperators">
    <error type="org.testng.TestException" message="
Method TrigonometricOperators.testTg()[pri:0, instance:com.epam.test.calculator.suites.test.negative.TrigonometricOperators@323b36e0] should have thrown an exception of type class java.lang.Exception">
      <![CDATA[org.testng.TestException: 
Method TrigonometricOperators.testTg()[pri:0, instance:com.epam.test.calculator.suites.test.negative.TrigonometricOperators@323b36e0] should have thrown an exception of type class java.lang.Exception
at org.testng.internal.ExpectedExceptionsHolder.noException(ExpectedExceptionsHolder.java:80)
at org.testng.internal.Invoker.considerExceptions(Invoker.java:1139)
at org.testng.internal.Invoker.invokeMethod(Invoker.java:612)
at org.testng.internal.Invoker.invokeTestMethod(Invoker.java:716)
at org.testng.internal.Invoker.invokeTestMethods(Invoker.java:988)
at org.testng.internal.TestMethodWorker.invokeTestMethods(TestMethodWorker.java:125)
at org.testng.internal.TestMethodWorker.run(TestMethodWorker.java:109)
at java.util.concurrent.ThreadPoolExecutor.runWorker(ThreadPoolExecutor.java:1149)
at java.util.concurrent.ThreadPoolExecutor$Worker.run(ThreadPoolExecutor.java:624)
at java.lang.Thread.run(Thread.java:748)
]]>
    </error>
  </testcase> <!-- testTg -->
</testsuite> <!-- com.epam.test.calculator.suites.test.negative.TrigonometricOperators -->
